<?xml version="1.0" encoding="utf-8"?>
<!-- This URDF was automatically created by SolidWorks to URDF Exporter! Originally created by Stephen Brawner (brawner@gmail.com) 
     Commit Version: 1.6.0-1-g15f4949  Build Version: 1.6.7594.29634
     For more information, please see http://wiki.ros.org/sw_urdf_exporter -->
<robot
  name="Wall-E-urdf1">
  <link
    name="base_link">
    <inertial>
      <origin
        xyz="-2.22044604925031E-16 5.55111512312578E-17 -0.0025"
        rpy="0 0 0" />
      <mass
        value="0.0915522076768964" />
      <inertia
        ixx="0.000121426493531278"
        ixy="1.28749007982654E-19"
        ixz="2.00582516820362E-22"
        iyy="0.000118984228490269"
        iyz="-4.40398066350633E-24"
        izz="0.00024002925448956" />
    </inertial>
    <visual>
      <origin
        xyz="0 0 0"
        rpy="0 0 0" />
      <geometry>
        <mesh
          filename="package://Wall-E-urdf1/meshes/base_link.STL" />
      </geometry>
      <material
        name="">
        <color
          rgba="1 1 0 1" />
      </material>
    </visual>
    <collision>
      <origin
        xyz="0 0 0"
        rpy="0 0 0" />
      <geometry>
        <mesh
          filename="package://Wall-E-urdf1/meshes/base_link.STL" />
      </geometry>
    </collision>
  </link>
  <link
    name="leftlink">
    <inertial>
      <origin
        xyz="1.30389649188878E-07 -0.0123100246668957 2.5334499642593E-07"
        rpy="0 0 0" />
      <mass
        value="0.0297341394891575" />
      <inertia
        ixx="1.22912877699104E-05"
        ixy="-4.10833231740425E-11"
        ixz="-1.60251566466151E-10"
        iyy="2.03788362258655E-05"
        iyz="-7.97922307819276E-11"
        izz="1.22911347079312E-05" />
    </inertial>
    <visual>
      <origin
        xyz="0 0 0"
        rpy="0 0 0" />
      <geometry>
        <mesh
          filename="package://Wall-E-urdf1/meshes/leftlink.STL" />
      </geometry>
      <material
        name="">
        <color
          rgba="0.792156862745098 0.819607843137255 0.933333333333333 1" />
      </material>
    </visual>
    <collision>
      <origin
        xyz="0 0 0"
        rpy="0 0 0" />
      <geometry>
        <mesh
          filename="package://Wall-E-urdf1/meshes/leftlink.STL" />
      </geometry>
    </collision>
  </link>
  <joint
    name="leftjoint"
    type="continuous">
    <origin
      xyz="-0.0054501 0.10601 -0.017901"
      rpy="0 0 0" />
    <parent
      link="base_link" />
    <child
      link="leftlink" />
    <axis
      xyz="0 -1 0" />
    <limit
      effort="1"
      velocity="1" />
  </joint>
  <link
    name="rightlink">
    <inertial>
      <origin
        xyz="1.30389644192874E-07 0.0123100246669055 -2.53345015299722E-07"
        rpy="0 0 0" />
      <mass
        value="0.0297341394891515" />
      <inertia
        ixx="1.22912877699023E-05"
        ixy="4.10833183756008E-11"
        ixz="1.60251568244731E-10"
        iyy="2.03788362258477E-05"
        iyz="-7.97922334315798E-11"
        izz="1.22911347079369E-05" />
    </inertial>
    <visual>
      <origin
        xyz="0 0 0"
        rpy="0 0 0" />
      <geometry>
        <mesh
          filename="package://Wall-E-urdf1/meshes/rightlink.STL" />
      </geometry>
      <material
        name="">
        <color
          rgba="0.792156862745098 0.819607843137255 0.933333333333333 1" />
      </material>
    </visual>
    <collision>
      <origin
        xyz="0 0 0"
        rpy="0 0 0" />
      <geometry>
        <mesh
          filename="package://Wall-E-urdf1/meshes/rightlink.STL" />
      </geometry>
    </collision>
  </link>
  <joint
    name="rightjoint"
    type="continuous">
    <origin
      xyz="-0.0063446 -0.10601 -0.017901"
      rpy="0 0 0" />
    <parent
      link="base_link" />
    <child
      link="rightlink" />
    <axis
      xyz="0 -1 0" />
    <limit
      effort="1"
      velocity="1" />
  </joint>
</robot>