<sdf version='1.7'>
  <model name='walle'>
    <link name='base_link'>
      <inertial>
        <pose>-0 0 -0.0025 0 -0 0</pose>
        <mass>0.0915522</mass>
        <inertia>
          <ixx>0.000121426</ixx>
          <ixy>1.28749e-19</ixy>
          <ixz>2.00583e-22</ixz>
          <iyy>0.000118984</iyy>
          <iyz>-4.40398e-24</iyz>
          <izz>0.000240029</izz>
        </inertia>
      </inertial>
      <collision name='base_link_collision'>
        <pose>0 0 0 0 -0 0</pose>
        <geometry>
          <mesh>
            <scale>1 1 1</scale>
            <uri>meshes/base_link.STL</uri>
          </mesh>
        </geometry>
      </collision>
      <visual name='base_link_visual'>
        <pose>0 0 0 0 -0 0</pose>
        <geometry>
          <mesh>
            <scale>1 1 1</scale>
            <uri>meshes/base_link.STL</uri>
          </mesh>
        </geometry>
      </visual>
    </link>
    <joint name='leftjoint' type='revolute'>
      <pose relative_to='base_link'>-0.00545 0.10601 -0.017901 0 -0 0</pose>
      <parent>base_link</parent>
      <child>leftlink</child>
      <axis>
        <xyz>0 -1 0</xyz>
        <limit>
          <effort>1</effort>
          <velocity>1</velocity>
          <lower>-1e+16</lower>
          <upper>1e+16</upper>
        </limit>
        <dynamics>
          <spring_reference>0</spring_reference>
          <spring_stiffness>0</spring_stiffness>
        </dynamics>
      </axis>
    </joint>
    <link name='leftlink'>
      <pose relative_to='leftjoint'>0 0 0 0 -0 0</pose>
      <inertial>
        <pose>0 -0.01231 0 0 -0 0</pose>
        <mass>0.0297341</mass>
        <inertia>
          <ixx>1.22913e-05</ixx>
          <ixy>-4.10833e-11</ixy>
          <ixz>-1.60252e-10</ixz>
          <iyy>2.03788e-05</iyy>
          <iyz>-7.97922e-11</iyz>
          <izz>1.22911e-05</izz>
        </inertia>
      </inertial>
      <collision name='leftlink_collision'>
        <pose>0 0 0 0 -0 0</pose>
        <geometry>
          <mesh>
            <scale>1 1 1</scale>
            <uri>meshes/leftlink.STL</uri>
          </mesh>
        </geometry>
      </collision>
      <visual name='leftlink_visual'>
        <pose>0 0 0 0 -0 0</pose>
        <geometry>
          <mesh>
            <scale>1 1 1</scale>
            <uri>meshes/leftlink.STL</uri>
          </mesh>
        </geometry>
      </visual>
    </link>
    <joint name='rightjoint' type='revolute'>
      <pose relative_to='base_link'>-0.006345 -0.10601 -0.017901 0 -0 0</pose>
      <parent>base_link</parent>
      <child>rightlink</child>
      <axis>
        <xyz>0 -1 0</xyz>
        <limit>
          <effort>1</effort>
          <velocity>1</velocity>
          <lower>-1e+16</lower>
          <upper>1e+16</upper>
        </limit>
        <dynamics>
          <spring_reference>0</spring_reference>
          <spring_stiffness>0</spring_stiffness>
        </dynamics>
      </axis>
    </joint>
    <link name='rightlink'>
      <pose relative_to='rightjoint'>0 0 0 0 -0 0</pose>
      <inertial>
        <pose>0 0.01231 -0 0 -0 0</pose>
        <mass>0.0297341</mass>
        <inertia>
          <ixx>1.22913e-05</ixx>
          <ixy>4.10833e-11</ixy>
          <ixz>1.60252e-10</ixz>
          <iyy>2.03788e-05</iyy>
          <iyz>-7.97922e-11</iyz>
          <izz>1.22911e-05</izz>
        </inertia>
      </inertial>
      <collision name='rightlink_collision'>
        <pose>0 0 0 0 -0 0</pose>
        <geometry>
          <mesh>
            <scale>1 1 1</scale>
            <uri>meshes/rightlink.STL</uri>
          </mesh>
        </geometry>
      </collision>
      <visual name='rightlink_visual'>
        <pose>0 0 0 0 -0 0</pose>
        <geometry>
          <mesh>
            <scale>1 1 1</scale>
            <uri>meshes/rightlink.STL</uri>
          </mesh>
        </geometry>
      </visual>
    </link>
  </model>
</sdf>
